<mujoco model="dex31 left hand">
  <statistic center="0.3 0 0.4" extent="1"/>
  <compiler angle="radian" meshdir="./" autolimits="true"/>

  <visual>
      <headlight diffuse="0.6 0.6 0.6" ambient="0.3 0.3 0.3" specular="0 0 0"/>
      <rgba haze="0.15 0.25 0.35 1"/>
      <global azimuth="120" elevation="20"/>
  </visual>

  <default>
      <joint damping="1"/>
      <muscle ctrllimited="true" ctrlrange="0 100"/>
      <motor ctrllimited="true" ctrlrange="-3 3" gear="1"/>
      <position ctrllimited="true" kp="10"/>
  </default>

  <asset>
    <mesh name="left_hand_palm_link" file="./meshes/left_hand_palm_link.STL"/>
    <mesh name="left_hand_thumb_0_link" file="./meshes/left_hand_thumb_0_link.STL"/>
    <mesh name="left_hand_thumb_1_link" file="./meshes/left_hand_thumb_1_link.STL"/>
    <mesh name="left_hand_thumb_2_link" file="./meshes/left_hand_thumb_2_link.STL"/>
    <mesh name="left_hand_middle_0_link" file="./meshes/left_hand_middle_0_link.STL"/>
    <mesh name="left_hand_middle_1_link" file="./meshes/left_hand_middle_1_link.STL"/>
    <mesh name="left_hand_index_0_link" file="./meshes/left_hand_index_0_link.STL"/>
    <mesh name="left_hand_index_1_link" file="./meshes/left_hand_index_1_link.STL"/>
    <!-- <mesh name="right_hand_palm_link" file="./meshes/right_hand_palm_link.STL"/>
    <mesh name="right_hand_thumb_0_link" file="./meshes/right_hand_thumb_0_link.STL"/>
    <mesh name="right_hand_thumb_1_link" file="./meshes/right_hand_thumb_1_link.STL"/>
    <mesh name="right_hand_thumb_2_link" file="./meshes/right_hand_thumb_2_link.STL"/>
    <mesh name="right_hand_middle_0_link" file="./meshes/right_hand_middle_0_link.STL"/>
    <mesh name="right_hand_middle_1_link" file="./meshes/right_hand_middle_1_link.STL"/>
    <mesh name="right_hand_index_0_link" file="./meshes/right_hand_index_0_link.STL"/>
    <mesh name="right_hand_index_1_link" file="./meshes/right_hand_index_1_link.STL"/> -->
  </asset>

  <worldbody>
    <body name="left_hand" pos="0 0 0" quat="0.7071068 0.7071068 0 0">
      <site name="ft_frame" pos="0 0 0" size="0.01 0.01 0.01" rgba="1 0 0 0" type="sphere" group="1"/>
      <inertial diaginertia="0 0 0" mass="0" pos="0 0 0"/>
      <body name="eef" pos="0 0 0" quat="0.707 0. -0.707 0.">
          <site name="grip_site" pos="0 0 0" size="0.01 0.01 0.01" rgba="1 1 0 1" type="sphere" group="2"/>
          <site name="ee_x" pos="0.1 0 0" size="0.005 .1"  quat="0.707105  0 0.707108 0 " rgba="1 0 0 0" type="cylinder" group="1"/>
          <site name="ee_y" pos="0 0.1 0" size="0.005 .1" quat="0.707105 0.707108 0 0" rgba="0 1 0 0" type="cylinder" group="1"/>
          <site name="ee_z" pos="0 0 0.1" size="0.005 .1" quat="1 0 0 0" rgba="0 0 1 0" type="cylinder" group="1"/>
          <!-- This site was added for visualization. -->
          <site name="grip_site_cylinder" pos="0 0 0" quat="-0.5 -0.5 -0.5 0.5" size="0.005 0.5" rgba="0 1 0 0.3" type="cylinder" group="1"/>
      </body>

      <geom pos="0.0415 0.003 0" quat="1 0 0 0" type="mesh" contype="0" conaffinity="0" group="1" density="0" rgba="0.7 0.7 0.7 1" mesh="left_hand_palm_link"/>
      <geom pos="0.0415 0.003 0" quat="1 0 0 0" type="mesh" rgba="0.7 0.7 0.7 1" mesh="left_hand_palm_link"/>
      <body name="left_hand_thumb_0_link" pos="0.067 0.003 0">
        <inertial pos="-0.000884246 -0.00863407 0.000944293" quat="0.462991 0.643965 -0.460173 0.398986" mass="0.0862366" diaginertia="1.6546e-05 1.60058e-05 1.43741e-05"/>
        <joint name="left_hand_thumb_0_joint" pos="0 0 0" axis="0 1 0" range="-1.0472 1.0472" actuatorfrcrange="-2.45 2.45"/>
        <geom type="mesh" contype="0" conaffinity="0" group="1" density="0" rgba="0.7 0.7 0.7 1" mesh="left_hand_thumb_0_link"/>
        <geom type="mesh" rgba="0.7 0.7 0.7 1" mesh="left_hand_thumb_0_link"/>
        <body name="left_hand_thumb_1_link" pos="-0.0025 -0.0193 0">
          <inertial pos="-0.000827888 -0.0354744 -0.0003809" quat="0.685598 0.705471 -0.15207 0.0956069" mass="0.0588507" diaginertia="1.28514e-05 1.22902e-05 5.9666e-06"/>
          <joint name="left_hand_thumb_1_joint" pos="0 0 0" axis="0 0 1" range="-0.724312 1.0472" actuatorfrcrange="-1.4 1.4"/>
          <geom type="mesh" contype="0" conaffinity="0" group="1" density="0" rgba="0.7 0.7 0.7 1" mesh="left_hand_thumb_1_link"/>
          <geom size="0.01 0.015 0.01" pos="-0.001 -0.032 0" type="box" rgba="0.7 0.7 0.7 1"/>
          <body name="left_hand_thumb_2_link" pos="0 -0.0458 0">
            <inertial pos="-0.00171735 -0.0262819 0.000107789" quat="0.703174 0.710977 -0.00017564 -0.00766553" mass="0.0203063" diaginertia="4.61314e-06 3.86645e-06 1.53495e-06"/>
            <joint name="left_hand_thumb_2_joint" pos="0 0 0" axis="0 0 1" range="0 1.74533" actuatorfrcrange="-1.4 1.4"/>
            <geom type="mesh" contype="0" conaffinity="0" group="1" density="0" rgba="0.7 0.7 0.7 1" mesh="left_hand_thumb_2_link"/>
            <geom type="mesh" rgba="0.7 0.7 0.7 1" mesh="left_hand_thumb_2_link"/>
          </body>
        </body>
      </body>
      <body name="left_hand_middle_0_link" pos="0.1192 0.0046 -0.0285">
        <inertial pos="0.0354744 0.000827888 0.0003809" quat="0.391313 0.552395 0.417187 0.606373" mass="0.0588507" diaginertia="1.28514e-05 1.22902e-05 5.9666e-06"/>
        <joint name="left_hand_middle_0_joint" pos="0 0 0" axis="0 0 1" range="-1.5708 0" actuatorfrcrange="-1.4 1.4"/>
        <geom type="mesh" contype="0" conaffinity="0" group="1" density="0" rgba="0.7 0.7 0.7 1" mesh="left_hand_middle_0_link"/>
        <geom type="mesh" rgba="0.7 0.7 0.7 1" mesh="left_hand_middle_0_link"/>
        <body name="left_hand_middle_1_link" pos="0.0458 0 0">
          <inertial pos="0.0262819 0.00171735 -0.000107789" quat="0.502612 0.491799 0.502639 0.502861" mass="0.0203063" diaginertia="4.61314e-06 3.86645e-06 1.53495e-06"/>
          <joint name="left_hand_middle_1_joint" pos="0 0 0" axis="0 0 1" range="-1.74533 0" actuatorfrcrange="-1.4 1.4"/>
          <geom type="mesh" contype="0" conaffinity="0" group="1" density="0" rgba="0.7 0.7 0.7 1" mesh="left_hand_middle_1_link"/>
          <geom type="mesh" rgba="0.7 0.7 0.7 1" mesh="left_hand_middle_1_link"/>
        </body>
      </body>
      <body name="left_hand_index_0_link" pos="0.1192 0.0046 0.0285">
        <inertial pos="0.0354744 0.000827888 0.0003809" quat="0.391313 0.552395 0.417187 0.606373" mass="0.0588507" diaginertia="1.28514e-05 1.22902e-05 5.9666e-06"/>
        <joint name="left_hand_index_0_joint" pos="0 0 0" axis="0 0 1" range="-1.5708 0" actuatorfrcrange="-1.4 1.4"/>
        <geom type="mesh" contype="0" conaffinity="0" group="1" density="0" rgba="0.7 0.7 0.7 1" mesh="left_hand_index_0_link"/>
        <geom type="mesh" rgba="0.7 0.7 0.7 1" mesh="left_hand_index_0_link"/>
        <body name="left_hand_index_1_link" pos="0.0458 0 0">
          <inertial pos="0.0262819 0.00171735 -0.000107789" quat="0.502612 0.491799 0.502639 0.502861" mass="0.0203063" diaginertia="4.61314e-06 3.86645e-06 1.53495e-06"/>
          <joint name="left_hand_index_1_joint" pos="0 0 0" axis="0 0 1" range="-1.74533 0" actuatorfrcrange="-1.4 1.4"/>
          <geom type="mesh" contype="0" conaffinity="0" group="1" density="0" rgba="0.7 0.7 0.7 1" mesh="left_hand_index_1_link"/>
          <geom type="mesh" rgba="0.7 0.7 0.7 1" mesh="left_hand_index_1_link"/>
        </body>
      </body>
    </body>

    <!-- <body name="left_hand" pos="0 0 0" quat="0.7071068 0.7071068 0 0">
      <site name="ft_frame" pos="0 0 0" size="0.01 0.01 0.01" rgba="1 0 0 0" type="sphere" group="1"/>
      <inertial diaginertia="0 0 0" mass="0" pos="0 0 0"/>
      <body name="eef" pos="0 0 0" quat="0.707 0. -0.707 0.">
          <site name="grip_site" pos="0 0 0" size="0.01 0.01 0.01" rgba="1 1 0 1" type="sphere" group="2"/>
          <site name="ee_x" pos="0.1 0 0" size="0.005 .1"  quat="0.707105  0 0.707108 0 " rgba="1 0 0 0" type="cylinder" group="1"/>
          <site name="ee_y" pos="0 0.1 0" size="0.005 .1" quat="0.707105 0.707108 0 0" rgba="0 1 0 0" type="cylinder" group="1"/>
          <site name="ee_z" pos="0 0 0.1" size="0.005 .1" quat="1 0 0 0" rgba="0 0 1 0" type="cylinder" group="1"/>
          <site name="grip_site_cylinder" pos="0 0 0" quat="-0.5 -0.5 -0.5 0.5" size="0.005 0.5" rgba="0 1 0 0.3" type="cylinder" group="1"/>
      </body> -->

      <!-- Palm  -->
      <!-- <body quat="0.5 -0.5 -0.5 -0.5">
      <body name="l_palm" pos="0 0 0">
        <geom name="l_palm_vis" type="mesh" material="l_base_material" mesh="L_hand_base_link_vis" group="1" contype="0" conaffinity="0"/>
        <geom name="l_palm_col" type="mesh" mass="0.1" mesh="L_hand_base_link_col"/> -->

        <!-- Thumb -->
        <!-- <body name="l_thumb" pos="0. 0. 0.">
          <body name="L_thumb_proximal_base_link" pos="0.022 -0.015498 -0.025093" quat="1 0 -6.105e-06 0">
            <joint name="L_thumb_proximal_yaw_joint" pos="0 0 0" axis="0 0 -1" range="0 1.74" actuatorfrcrange="-10 10" damping="1"/>
            <geom name="L_thumb_proximal_base_link_vis" type="mesh" material="l_thumb_material" mesh="L_thumb_proximal_base_link_vis" group="1" contype="0" conaffinity="0"/>
            <geom name="L_thumb_proximal_base_link_col" type="mesh" mass="0.1" mesh="L_thumb_proximal_base_link_col"/>
            <body name="L_thumb_proximal_link" pos="0.02175 0 0" quat="0.707141 -0.707073 0 0">
              <site name="site_L_thumb_proximal_link" size="0.01" material="site_left_hand"/>
              <joint name="L_thumb_proximal_pitch_joint" pos="0 0 0" axis="0 0 1" range="0 1.22" actuatorfrcrange="-10 10" damping="1"/>
              <geom name="L_thumb_proximal_link_vis" type="mesh" material="l_thumb_material" mesh="L_thumb_proximal_link_vis" group="1" contype="0" conaffinity="0"/>
              <geom name="L_thumb_proximal_link_col" type="mesh" mass="0.1" mesh="L_thumb_proximal_link_col"/>
              <body name="L_thumb_distal_link" pos="0.061549 0.0074616 0" quat="1 0 0 6.105e-06">
                <site name="site_L_thumb_distal_link" size="0.01" material="site_left_hand"/>
                <joint name="L_thumb_distal_joint" pos="0 0 0" axis="0 0 1" range="0 1.23" actuatorfrcrange="-10 10" damping="1"/>
                <geom name="L_thumb_distal_link_vis" type="mesh" material="l_thumb_material" mesh="L_thumb_distal_link_vis" group="1" contype="0" conaffinity="0"/>
                <geom name="L_thumb_distal_link_col" type="mesh" mass="0.1" mesh="L_thumb_distal_link_col"/>
              </body>
            </body>
          </body>
        </body> -->
        <!-- End of Thumb -->

        <!-- Index -->
        <!-- <body name="l_index" pos="0 0 0">
          <body name="L_index_proximal_link" pos="0.026869 -0.012293 -0.095989" quat="0.725387 2.48047e-05 0.688341 2.35323e-05">
            <site name="site_L_index_proximal_link" size="0.01" material="site_left_hand"/>
            <joint name="L_index_proximal_joint" pos="0 0 0" axis="0 0 -1" range="0 1.57" actuatorfrcrange="-10 10" damping="1"/>
            <geom name="L_index_proximal_link_vis" type="mesh" material="l_index_material" mesh="L_index_proximal_link_vis" group="1" contype="0" conaffinity="0"/>
            <geom name="L_index_proximal_link_col" type="mesh" mass="0.1" mesh="L_index_proximal_link_col"/>
            <body name="L_index_intermediate_link" pos="0.031532 -0.0054551 0" quat="1 0 0 -3.4128e-05">
              <site name="site_L_index_intermediate_link" size="0.01" material="site_left_hand"/>
              <joint name="L_index_intermediate_joint" pos="0 0 0" axis="0 0 -1" range="0 1.74" actuatorfrcrange="-10 10" damping="1"/>
              <geom name="L_index_intermediate_link_vis" type="mesh" material="l_index_material" mesh="L_index_intermediate_link_vis" group="1" contype="0" conaffinity="0"/>
              <geom name="L_index_intermediate_link_col" type="mesh" mass="0.1" mesh="L_index_intermediate_link_col"/>
            </body>
          </body>
        </body> -->
        <!-- End of Index -->

        <!-- Middle -->
        <!-- <body name="l_middle" pos="0 0 0">
          <body name="L_middle_proximal_link" pos="0.0085012 -0.012293 -0.097993" quat="0.707113 3.35258e-05 0.707101 3.35258e-05">
            <site name="site_L_middle_proximal_link" size="0.01" material="site_left_hand"/>
            <joint name="L_middle_proximal_joint" pos="0 0 0" axis="0 0 -1" range="0 1.57" actuatorfrcrange="-10 10" damping="1"/>
            <geom name="L_middle_proximal_link_vis" type="mesh" material="l_middle_material" mesh="L_middle_proximal_link_vis" group="1" contype="0" conaffinity="0"/>
            <geom name="L_middle_proximal_link_col" type="mesh" mass="0.1" mesh="L_middle_proximal_link_col"/>
            <body name="L_middle_intermediate_link" pos="0.031662 -0.0046408 0" quat="1 0 0 -3.4175e-05">
              <site name="site_L_middle_intermediate_link" size="0.01" material="site_left_hand"/>
              <joint name="L_middle_intermediate_joint" pos="0 0 0" axis="0 0 -1" range="0 1.74" actuatorfrcrange="-10 10" damping="1"/>
              <geom name="L_middle_intermediate_link_vis" type="mesh" material="l_middle_material" mesh="L_middle_intermediate_link_vis" group="1" contype="0" conaffinity="0"/>
              <geom name="L_middle_intermediate_link_col" type="mesh" mass="0.1" mesh="L_middle_intermediate_link_col"/>
            </body>
          </body>
        </body> -->
        <!-- End of Middle -->

        <!-- Ring -->
        <!-- <body name="l_ring" pos="0 0 0">
          <body name="L_ring_proximal_link" pos="-0.00996 -0.012293 -0.097938" quat="0.688341 2.39435e-05 0.725387 2.39435e-05">
            <site name="site_L_ring_proximal_link" size="0.01" material="site_left_hand"/>
            <joint name="L_ring_proximal_joint" pos="0 0 0" axis="0 0 -1" range="0 1.57" actuatorfrcrange="-10 10" damping="1"/>
            <geom name="L_ring_proximal_link_vis" type="mesh" material="l_ring_material" mesh="L_ring_proximal_link_vis" group="1" contype="0" conaffinity="0"/>
            <geom name="L_ring_proximal_link_col" type="mesh" mass="0.1" mesh="L_ring_proximal_link_col"/>
            <body name="L_ring_intermediate_link" pos="0.031532 -0.0054551 0" quat="1 0 0 -3.4128e-05">
              <site name="site_L_ring_intermediate_link" size="0.01" material="site_left_hand"/>
              <joint name="L_ring_intermediate_joint" pos="0 0 0" axis="0 0 -1" range="0 1.74" actuatorfrcrange="-10 10" damping="1"/>
              <geom name="L_ring_intermediate_link_vis" type="mesh" material="l_ring_material" mesh="L_ring_intermediate_link_vis" group="1" contype="0" conaffinity="0"/>
              <geom name="L_ring_intermediate_link_col" type="mesh" mass="0.1" mesh="L_ring_intermediate_link_col"/>
            </body>
          </body>
        </body> -->

        <!-- Pinky finger -->
        <!-- <body name="l_pinky" pos="0 0 0">
          <body name="L_pinky_proximal_link" pos="-0.028227 -0.012293 -0.096013" quat="0.669139 2.56274e-05 0.743137 2.56274e-05">
            <site name="site_L_pinky_proximal_link" size="0.01" material="site_left_hand"/>
            <joint name="L_pinky_proximal_joint" pos="0 0 0" axis="0 0 -1" range="0 1.57" actuatorfrcrange="-10 10" damping="1"/>
            <geom name="L_pinky_proximal_link_vis" type="mesh" material="l_pinky_material" mesh="L_pinky_proximal_link_vis" group="1" contype="0" conaffinity="0"/>
            <geom name="L_pinky_proximal_link_col" type="mesh" mass="0.1" mesh="L_pinky_proximal_link_col"/>
            <body name="L_pinky_intermediate_link" pos="0.031338 -0.0064763 0" quat="1 0 0 -3.3988e-05">
              <site name="site_L_pinky_intermediate_link" size="0.01" material="site_left_hand"/>
              <joint name="L_pinky_intermediate_joint" pos="0 0 0" axis="0 0 -1" range="0 1.74" actuatorfrcrange="-10 10" damping="1"/>
              <geom name="L_pinky_intermediate_link_vis" type="mesh" material="l_pinky_material" mesh="L_pinky_intermediate_link_vis" group="1" contype="0" conaffinity="0"/>
              <geom name="L_pinky_intermediate_link_col" type="mesh" mass="0.1" mesh="L_pinky_intermediate_link_col"/>
            </body>
          </body>
        </body> -->
        <!-- End of Pinky finger -->
      <!-- </body>
      </body> -->
      <!-- End of Palm -->
    <!-- </body> -->
  </worldbody>

  <actuator>
    <position joint="left_hand_thumb_0_joint" name="left_hand_thumb_0_joint_drive" ctrlrange="0 1.74" kp="2" forcelimited="true" forcerange="-20 20"/>
  left_hand_thumb_1_joint
  left_hand_thumb_2_joint
  left_hand_middle_0_joint
  left_hand_middle_1_joint
  left_hand_index_0_joint
  left_hand_index_1_joint

    <position joint="left_hand_thumb_0_joint" name="left_hand_thumb_0_joint_drive" ctrlrange="-1.0472 1.0472" kp="2" forcelimited="true" forcerange="-2.45 2.45"/>
    <position joint="left_hand_thumb_1_joint" name="left_hand_thumb_1_joint_drive" ctrlrange="-0.724312 1.0472" kp="2" forcelimited="true" forcerange="-1.4 1.4"/>
    <position joint="left_hand_thumb_2_joint" name="left_hand_thumb_2_joint_drive" ctrlrange="0 1.74533" kp="2" forcelimited="true" forcerange="-1.4 1.4"/>
    <position joint="left_hand_middle_0_joint" name="left_hand_middle_0_joint_drive" ctrlrange="-1.5708 0" kp="2" forcelimited="true" forcerange="-1.4 1.4"/>
    <position joint="left_hand_middle_1_joint" name="left_hand_middle_1_joint_drive" ctrlrange="-1.74533 0" kp="2" forcelimited="true" forcerange="-1.4 1.4"/>
    <position joint="left_hand_index_0_joint" name="left_hand_index_0_joint_drive" ctrlrange="-1.5708 0" kp="2" forcelimited="true" forcerange="-1.4 1.4"/>
    <position joint="left_hand_index_1_joint" name="left_hand_index_1_joint_drive" ctrlrange="-1.74533 0" kp="2" forcelimited="true" forcerange="-1.4 1.4"/>
  </actuator>

  <sensor>
        <force name="force_ee" site="ft_frame"/>
        <torque name="torque_ee" site="ft_frame"/>
  </sensor>
</mujoco>
